Workbook

Sheet Год 2026
A1: ГОД 2026 🩷 сводка по месяцам
A2: данные тянутся из вкладок-месяцев автоматически (факт)
A4: Месяц | B4: Доход | C4: Сбережения | D4: Постоянные | E4: Переменные | F4: Остаток
A5: Январь | B5: =Январь!C6 -> 0 | C5: =Январь!C7 -> 0 | D5: =Январь!C8 -> 0 | E5: =Январь!C9 -> 0 | F5: =Январь!C10 -> 0
A6: Февраль | B6: =Февраль!C6 -> 0 | C6: =Февраль!C7 -> 0 | D6: =Февраль!C8 -> 0 | E6: =Февраль!C9 -> 0 | F6: =Февраль!C10 -> 0
A7: Март | B7: =Март!C6 -> 0 | C7: =Март!C7 -> 0 | D7: =Март!C8 -> 0 | E7: =Март!C9 -> 0 | F7: =Март!C10 -> 0
A8: Апрель | B8: =Апрель!C6 -> 0 | C8: =Апрель!C7 -> 0 | D8: =Апрель!C8 -> 0 | E8: =Апрель!C9 -> 0 | F8: =Апрель!C10 -> 0
A9: Май | B9: =Май!C6 -> 0 | C9: =Май!C7 -> 0 | D9: =Май!C8 -> 0 | E9: =Май!C9 -> 0 | F9: =Май!C10 -> 0
A10: Июнь | B10: =Июнь!C6 -> 217000 | C10: =Июнь!C7 -> 18000 | D10: =Июнь!C8 -> 93600 | E10: =Июнь!C9 -> 119360 | F10: =Июнь!C10 -> -13960
A11: Июль | B11: =Июль!C6 -> 0 | C11: =Июль!C7 -> 0 | D11: =Июль!C8 -> 0 | E11: =Июль!C9 -> 0 | F11: =Июль!C10 -> 0
A12: Август | B12: =Август!C6 -> 0 | C12: =Август!C7 -> 0 | D12: =Август!C8 -> 0 | E12: =Август!C9 -> 0 | F12: =Август!C10 -> 0
A13: Сентябрь | B13: =Сентябрь!C6 -> 0 | C13: =Сентябрь!C7 -> 0 | D13: =Сентябрь!C8 -> 0 | E13: =Сентябрь!C9 -> 0 | F13: =Сентябрь!C10 -> 0
A14: Октябрь | B14: =Октябрь!C6 -> 0 | C14: =Октябрь!C7 -> 0 | D14: =Октябрь!C8 -> 0 | E14: =Октябрь!C9 -> 0 | F14: =Октябрь!C10 -> 0
A15: Ноябрь | B15: =Ноябрь!C6 -> 0 | C15: =Ноябрь!C7 -> 0 | D15: =Ноябрь!C8 -> 0 | E15: =Ноябрь!C9 -> 0 | F15: =Ноябрь!C10 -> 0
A16: Декабрь | B16: =Декабрь!C6 -> 0 | C16: =Декабрь!C7 -> 0 | D16: =Декабрь!C8 -> 0 | E16: =Декабрь!C9 -> 0 | F16: =Декабрь!C10 -> 0
A17: 1-е полугодие | B17: =SUM(B5:B10) -> 217000 | C17: =SUM(C5:C10) -> 18000 | D17: =SUM(D5:D10) -> 93600 | E17: =SUM(E5:E10) -> 119360 | F17: =SUM(F5:F10) -> -13960
A18: 2-е полугодие | B18: =SUM(B11:B16) -> 0 | C18: =SUM(C11:C16) -> 0 | D18: =SUM(D11:D16) -> 0 | E18: =SUM(E11:E16) -> 0 | F18: =SUM(F11:F16) -> 0
A19: ЗА ГОД | B19: =SUM(B5:B16) -> 217000 | C19: =SUM(C5:C16) -> 18000 | D19: =SUM(D5:D16) -> 93600 | E19: =SUM(E5:E16) -> 119360 | F19: =SUM(F5:F16) -> -13960
A21: Как пользоваться: внизу — вкладки по месяцам, кликай нужный и заполняй. Эта вкладка собирает итоги сама 🩷

Sheet Январь
A1: МОЙ БЮДЖЕТ 🩷 Январь 2026
A2: не по сценарию · веду деньги без занудства
A4: 📊 СВОДКА ЗА МЕСЯЦ
A5: статья | B5: план | C5: факт | D5: разница
A6: 💰 Доходы | B6: =B22 -> 0 | C6: =C22 -> 0 | D6: =C6-B6 -> 0
A7: 🐷 Сбережения | B7: =B31 -> 0 | C7: =C31 -> 0 | D7: =C7-B7 -> 0
A8: 🏠 Постоянные расходы | B8: =B43 -> 0 | C8: =C43 -> 0 | D8: =B8-C8 -> 0
A9: 🛒 Переменные расходы | B9: =B63 -> 0 | C9: =C63 -> 0 | D9: =B9-C9 -> 0
A10: 🟢 Свободный остаток | B10: =B6-B7-B8-B9 -> 0 | C10: =C6-C7-C8-C9 -> 0 | D10: =C10-B10 -> 0
A13: 💰 ДОХОДЫ
A14: статья | B14: план | C14: факт | D14: разница
A15: Зарплата | D15: =C15-B15 -> 0
A16: Бонус/премия | D16: =C16-B16 -> 0
A17: Фриланс/подработка | D17: =C17-B17 -> 0
A18: Блог | D18: =C18-B18 -> 0
A19: Кэшбэк/проценты | D19: =C19-B19 -> 0
A20: Прочее | D20: =C20-B20 -> 0
A22: ВСЕГО | B22: =SUM(B15:B21) -> 0 | C22: =SUM(C15:C21) -> 0 | D22: =C22-B22 -> 0
A24: 🐷 СБЕРЕЖЕНИЯ
A25: статья | B25: план | C25: факт | D25: разница
A26: Финансовая подушка | D26: =C26-B26 -> 0
A27: Отпуск | D27: =C27-B27 -> 0
A28: Крупная цель | D28: =C28-B28 -> 0
A29: Налоги/запас | D29: =C29-B29 -> 0
A30: Прочее | D30: =C30-B30 -> 0
A31: ВСЕГО | B31: =SUM(B26:B30) -> 0 | C31: =SUM(C26:C30) -> 0 | D31: =C31-B31 -> 0
A33: 🏠 ПОСТОЯННЫЕ РАСХОДЫ
A34: статья | B34: план | C34: факт | D34: экономия
A35: Аренда/ипотека | D35: =B35-C35 -> 0
A36: Коммуналка | D36: =B36-C36 -> 0
A37: Связь/интернет | D37: =B37-C37 -> 0
A38: Кредиты | D38: =B38-C38 -> 0
A39: Страховка | D39: =B39-C39 -> 0
A40: Детсад/школа | D40: =B40-C40 -> 0
A41: Абонементы | D41: =B41-C41 -> 0
A42: Прочее | D42: =B42-C42 -> 0
A43: ВСЕГО | B43: =SUM(B35:B42) -> 0 | C43: =SUM(C35:C42) -> 0 | D43: =B43-C43 -> 0
A45: 🛒 ПЕРЕМЕННЫЕ РАСХОДЫ
A46: статья | B46: план | C46: факт | D46: экономия
A47: Продукты | D47: =B47-C47 -> 0
...

Sheet Февраль
A1: МОЙ БЮДЖЕТ 🩷 Февраль 2026
A2: не по сценарию · веду деньги без занудства
A4: 📊 СВОДКА ЗА МЕСЯЦ
A5: статья | B5: план | C5: факт | D5: разница
A6: 💰 Доходы | B6: =B22 -> 0 | C6: =C22 -> 0 | D6: =C6-B6 -> 0
A7: 🐷 Сбережения | B7: =B31 -> 0 | C7: =C31 -> 0 | D7: =C7-B7 -> 0
A8: 🏠 Постоянные расходы | B8: =B43 -> 0 | C8: =C43 -> 0 | D8: =B8-C8 -> 0
A9: 🛒 Переменные расходы | B9: =B63 -> 0 | C9: =C63 -> 0 | D9: =B9-C9 -> 0
A10: 🟢 Свободный остаток | B10: =B6-B7-B8-B9 -> 0 | C10: =C6-C7-C8-C9 -> 0 | D10: =C10-B10 -> 0
A13: 💰 ДОХОДЫ
A14: статья | B14: план | C14: факт | D14: разница
A15: Зарплата | D15: =C15-B15 -> 0
A16: Бонус/премия | D16: =C16-B16 -> 0
A17: Фриланс/подработка | D17: =C17-B17 -> 0
A18: Блог | D18: =C18-B18 -> 0
A19: Кэшбэк/проценты | D19: =C19-B19 -> 0
A20: Прочее | D20: =C20-B20 -> 0
A22: ВСЕГО | B22: =SUM(B15:B21) -> 0 | C22: =SUM(C15:C21) -> 0 | D22: =C22-B22 -> 0
A24: 🐷 СБЕРЕЖЕНИЯ
A25: статья | B25: план | C25: факт | D25: разница
A26: Финансовая подушка | D26: =C26-B26 -> 0
A27: Отпуск | D27: =C27-B27 -> 0
A28: Крупная цель | D28: =C28-B28 -> 0
A29: Налоги/запас | D29: =C29-B29 -> 0
A30: Прочее | D30: =C30-B30 -> 0
A31: ВСЕГО | B31: =SUM(B26:B30) -> 0 | C31: =SUM(C26:C30) -> 0 | D31: =C31-B31 -> 0
A33: 🏠 ПОСТОЯННЫЕ РАСХОДЫ
A34: статья | B34: план | C34: факт | D34: экономия
A35: Аренда/ипотека | D35: =B35-C35 -> 0
A36: Коммуналка | D36: =B36-C36 -> 0
A37: Связь/интернет | D37: =B37-C37 -> 0
A38: Кредиты | D38: =B38-C38 -> 0
A39: Страховка | D39: =B39-C39 -> 0
A40: Детсад/школа | D40: =B40-C40 -> 0
A41: Абонементы | D41: =B41-C41 -> 0
A42: Прочее | D42: =B42-C42 -> 0
A43: ВСЕГО | B43: =SUM(B35:B42) -> 0 | C43: =SUM(C35:C42) -> 0 | D43: =B43-C43 -> 0
A45: 🛒 ПЕРЕМЕННЫЕ РАСХОДЫ
A46: статья | B46: план | C46: факт | D46: экономия
A47: Продукты | D47: =B47-C47 -> 0
...

Sheet Март
A1: МОЙ БЮДЖЕТ 🩷 Март 2026
A2: не по сценарию · веду деньги без занудства
A4: 📊 СВОДКА ЗА МЕСЯЦ
A5: статья | B5: план | C5: факт | D5: разница
A6: 💰 Доходы | B6: =B22 -> 0 | C6: =C22 -> 0 | D6: =C6-B6 -> 0
A7: 🐷 Сбережения | B7: =B31 -> 0 | C7: =C31 -> 0 | D7: =C7-B7 -> 0
A8: 🏠 Постоянные расходы | B8: =B43 -> 0 | C8: =C43 -> 0 | D8: =B8-C8 -> 0
A9: 🛒 Переменные расходы | B9: =B63 -> 0 | C9: =C63 -> 0 | D9: =B9-C9 -> 0
A10: 🟢 Свободный остаток | B10: =B6-B7-B8-B9 -> 0 | C10: =C6-C7-C8-C9 -> 0 | D10: =C10-B10 -> 0
A13: 💰 ДОХОДЫ
A14: статья | B14: план | C14: факт | D14: разница
A15: Зарплата | D15: =C15-B15 -> 0
A16: Бонус/премия | D16: =C16-B16 -> 0
A17: Фриланс/подработка | D17: =C17-B17 -> 0
A18: Блог | D18: =C18-B18 -> 0
A19: Кэшбэк/проценты | D19: =C19-B19 -> 0
A20: Прочее | D20: =C20-B20 -> 0
A22: ВСЕГО | B22: =SUM(B15:B21) -> 0 | C22: =SUM(C15:C21) -> 0 | D22: =C22-B22 -> 0
A24: 🐷 СБЕРЕЖЕНИЯ
A25: статья | B25: план | C25: факт | D25: разница
A26: Финансовая подушка | D26: =C26-B26 -> 0
A27: Отпуск | D27: =C27-B27 -> 0
A28: Крупная цель | D28: =C28-B28 -> 0
A29: Налоги/запас | D29: =C29-B29 -> 0
A30: Прочее | D30: =C30-B30 -> 0
A31: ВСЕГО | B31: =SUM(B26:B30) -> 0 | C31: =SUM(C26:C30) -> 0 | D31: =C31-B31 -> 0
A33: 🏠 ПОСТОЯННЫЕ РАСХОДЫ
A34: статья | B34: план | C34: факт | D34: экономия
A35: Аренда/ипотека | D35: =B35-C35 -> 0
A36: Коммуналка | D36: =B36-C36 -> 0
A37: Связь/интернет | D37: =B37-C37 -> 0
A38: Кредиты | D38: =B38-C38 -> 0
A39: Страховка | D39: =B39-C39 -> 0
A40: Детсад/школа | D40: =B40-C40 -> 0
A41: Абонементы | D41: =B41-C41 -> 0
A42: Прочее | D42: =B42-C42 -> 0
A43: ВСЕГО | B43: =SUM(B35:B42) -> 0 | C43: =SUM(C35:C42) -> 0 | D43: =B43-C43 -> 0
A45: 🛒 ПЕРЕМЕННЫЕ РАСХОДЫ
A46: статья | B46: план | C46: факт | D46: экономия
A47: Продукты | D47: =B47-C47 -> 0
...

Sheet Апрель
A1: МОЙ БЮДЖЕТ 🩷 Апрель 2026
A2: не по сценарию · веду деньги без занудства
A4: 📊 СВОДКА ЗА МЕСЯЦ
A5: статья | B5: план | C5: факт | D5: разница
A6: 💰 Доходы | B6: =B22 -> 0 | C6: =C22 -> 0 | D6: =C6-B6 -> 0
A7: 🐷 Сбережения | B7: =B31 -> 0 | C7: =C31 -> 0 | D7: =C7-B7 -> 0
A8: 🏠 Постоянные расходы | B8: =B43 -> 0 | C8: =C43 -> 0 | D8: =B8-C8 -> 0
A9: 🛒 Переменные расходы | B9: =B63 -> 0 | C9: =C63 -> 0 | D9: =B9-C9 -> 0
A10: 🟢 Свободный остаток | B10: =B6-B7-B8-B9 -> 0 | C10: =C6-C7-C8-C9 -> 0 | D10: =C10-B10 -> 0
A13: 💰 ДОХОДЫ
A14: статья | B14: план | C14: факт | D14: разница
A15: Зарплата | D15: =C15-B15 -> 0
A16: Бонус/премия | D16: =C16-B16 -> 0
A17: Фриланс/подработка | D17: =C17-B17 -> 0
A18: Блог | D18: =C18-B18 -> 0
A19: Кэшбэк/проценты | D19: =C19-B19 -> 0
A20: Прочее | D20: =C20-B20 -> 0
A22: ВСЕГО | B22: =SUM(B15:B21) -> 0 | C22: =SUM(C15:C21) -> 0 | D22: =C22-B22 -> 0
A24: 🐷 СБЕРЕЖЕНИЯ
A25: статья | B25: план | C25: факт | D25: разница
A26: Финансовая подушка | D26: =C26-B26 -> 0
A27: Отпуск | D27: =C27-B27 -> 0
A28: Крупная цель | D28: =C28-B28 -> 0
A29: Налоги/запас | D29: =C29-B29 -> 0
A30: Прочее | D30: =C30-B30 -> 0
A31: ВСЕГО | B31: =SUM(B26:B30) -> 0 | C31: =SUM(C26:C30) -> 0 | D31: =C31-B31 -> 0
A33: 🏠 ПОСТОЯННЫЕ РАСХОДЫ
A34: статья | B34: план | C34: факт | D34: экономия
A35: Аренда/ипотека | D35: =B35-C35 -> 0
A36: Коммуналка | D36: =B36-C36 -> 0
A37: Связь/интернет | D37: =B37-C37 -> 0
A38: Кредиты | D38: =B38-C38 -> 0
A39: Страховка | D39: =B39-C39 -> 0
A40: Детсад/школа | D40: =B40-C40 -> 0
A41: Абонементы | D41: =B41-C41 -> 0
A42: Прочее | D42: =B42-C42 -> 0
A43: ВСЕГО | B43: =SUM(B35:B42) -> 0 | C43: =SUM(C35:C42) -> 0 | D43: =B43-C43 -> 0
A45: 🛒 ПЕРЕМЕННЫЕ РАСХОДЫ
A46: статья | B46: план | C46: факт | D46: экономия
A47: Продукты | D47: =B47-C47 -> 0
...

Sheet Май
A1: МОЙ БЮДЖЕТ 🩷 Май 2026
A2: не по сценарию · веду деньги без занудства
A4: 📊 СВОДКА ЗА МЕСЯЦ
A5: статья | B5: план | C5: факт | D5: разница
A6: 💰 Доходы | B6: =B22 -> 0 | C6: =C22 -> 0 | D6: =C6-B6 -> 0
A7: 🐷 Сбережения | B7: =B31 -> 0 | C7: =C31 -> 0 | D7: =C7-B7 -> 0
A8: 🏠 Постоянные расходы | B8: =B43 -> 0 | C8: =C43 -> 0 | D8: =B8-C8 -> 0
A9: 🛒 Переменные расходы | B9: =B63 -> 0 | C9: =C63 -> 0 | D9: =B9-C9 -> 0
A10: 🟢 Свободный остаток | B10: =B6-B7-B8-B9 -> 0 | C10: =C6-C7-C8-C9 -> 0 | D10: =C10-B10 -> 0
A13: 💰 ДОХОДЫ
A14: статья | B14: план | C14: факт | D14: разница
A15: Зарплата | D15: =C15-B15 -> 0
A16: Бонус/премия | D16: =C16-B16 -> 0
A17: Фриланс/подработка | D17: =C17-B17 -> 0
A18: Блог | D18: =C18-B18 -> 0
A19: Кэшбэк/проценты | D19: =C19-B19 -> 0
A20: Прочее | D20: =C20-B20 -> 0
A22: ВСЕГО | B22: =SUM(B15:B21) -> 0 | C22: =SUM(C15:C21) -> 0 | D22: =C22-B22 -> 0
A24: 🐷 СБЕРЕЖЕНИЯ
A25: статья | B25: план | C25: факт | D25: разница
A26: Финансовая подушка | D26: =C26-B26 -> 0
A27: Отпуск | D27: =C27-B27 -> 0
A28: Крупная цель | D28: =C28-B28 -> 0
A29: Налоги/запас | D29: =C29-B29 -> 0
A30: Прочее | D30: =C30-B30 -> 0
A31: ВСЕГО | B31: =SUM(B26:B30) -> 0 | C31: =SUM(C26:C30) -> 0 | D31: =C31-B31 -> 0
A33: 🏠 ПОСТОЯННЫЕ РАСХОДЫ
A34: статья | B34: план | C34: факт | D34: экономия
A35: Аренда/ипотека | D35: =B35-C35 -> 0
A36: Коммуналка | D36: =B36-C36 -> 0
A37: Связь/интернет | D37: =B37-C37 -> 0
A38: Кредиты | D38: =B38-C38 -> 0
A39: Страховка | D39: =B39-C39 -> 0
A40: Детсад/школа | D40: =B40-C40 -> 0
A41: Абонементы | D41: =B41-C41 -> 0
A42: Прочее | D42: =B42-C42 -> 0
A43: ВСЕГО | B43: =SUM(B35:B42) -> 0 | C43: =SUM(C35:C42) -> 0 | D43: =B43-C43 -> 0
A45: 🛒 ПЕРЕМЕННЫЕ РАСХОДЫ
A46: статья | B46: план | C46: факт | D46: экономия
A47: Продукты | D47: =B47-C47 -> 0
...

Sheet Июнь
A1: МОЙ БЮДЖЕТ 🩷 Июнь 2026
A2: не по сценарию · веду деньги без занудства
A4: 📊 СВОДКА ЗА МЕСЯЦ
A5: статья | B5: план | C5: факт | D5: разница
A6: 💰 Доходы | B6: =B22 -> 235000 | C6: =C22 -> 217000 | D6: =C6-B6 -> -18000
A7: 🐷 Сбережения | B7: =B31 -> 16000 | C7: =C31 -> 18000 | D7: =C7-B7 -> 2000
A8: 🏠 Постоянные расходы | B8: =B43 -> 91600 | C8: =C43 -> 93600 | D8: =B8-C8 -> -2000
A9: 🛒 Переменные расходы | B9: =B63 -> 123560 | C9: =C63 -> 119360 | D9: =B9-C9 -> 4200
A10: 🟢 Свободный остаток | B10: =B6-B7-B8-B9 -> 3840 | C10: =C6-C7-C8-C9 -> -13960 | D10: =C10-B10 -> -17800
A13: 💰 ДОХОДЫ
A14: статья | B14: план | C14: факт | D14: разница
A15: Зарплата | B15: 200000 | C15: 200000 | D15: =C15-B15 -> 0
A16: Бонус/премия | B16: 20000 | C16: 10000 | D16: =C16-B16 -> -10000
A17: Фриланс/подработка | B17: 15000 | C17: 5000 | D17: =C17-B17 -> -10000
A18: Блог | B18: 0 | C18: 2000 | D18: =C18-B18 -> 2000
A19: Кэшбэк/проценты | B19: 0 | C19: 0 | D19: =C19-B19 -> 0
A20: Прочее | B20: 0 | C20: 0 | D20: =C20-B20 -> 0
A22: ВСЕГО | B22: =SUM(B15:B21) -> 235000 | C22: =SUM(C15:C21) -> 217000 | D22: =C22-B22 -> -18000
A24: 🐷 СБЕРЕЖЕНИЯ
A25: статья | B25: план | C25: факт | D25: разница
A26: Финансовая подушка | B26: 5000 | C26: 7000 | D26: =C26-B26 -> 2000
A27: Отпуск | B27: 10000 | C27: 10000 | D27: =C27-B27 -> 0
A28: Крупная цель | B28: 0 | C28: 0 | D28: =C28-B28 -> 0
A29: Налоги/запас | B29: 1000 | C29: 1000 | D29: =C29-B29 -> 0
A30: Прочее | B30: 0 | C30: 0 | D30: =C30-B30 -> 0
A31: ВСЕГО | B31: =SUM(B26:B30) -> 16000 | C31: =SUM(C26:C30) -> 18000 | D31: =C31-B31 -> 2000
A33: 🏠 ПОСТОЯННЫЕ РАСХОДЫ
A34: статья | B34: план | C34: факт | D34: экономия
A35: Аренда/ипотека | B35: 50000 | C35: 50000 | D35: =B35-C35 -> 0
A36: Коммуналка | B36: 10000 | C36: 12000 | D36: =B36-C36 -> -2000
A37: Связь/интернет | B37: 500 | C37: 500 | D37: =B37-C37 -> 0
A38: Кредиты | B38: 15800 | C38: 15800 | D38: =B38-C38 -> 0
A39: Страховка | B39: 300 | C39: 300 | D39: =B39-C39 -> 0
A40: Детсад/школа | B40: 15000 | C40: 15000 | D40: =B40-C40 -> 0
A41: Абонементы | B41: 0 | C41: 0 | D41: =B41-C41 -> 0
A42: Прочее | B42: 0 | C42: 0 | D42: =B42-C42 -> 0
A43: ВСЕГО | B43: =SUM(B35:B42) -> 91600 | C43: =SUM(C35:C42) -> 93600 | D43: =B43-C43 -> -2000
A45: 🛒 ПЕРЕМЕННЫЕ РАСХОДЫ
A46: статья | B46: план | C46: факт | D46: экономия
A47: Продукты | B47: 30000 | C47: 28000 | D47: =B47-C47 -> 2000
...

Sheet Июль
A1: МОЙ БЮДЖЕТ 🩷 Июль 2026
A2: не по сценарию · веду деньги без занудства
A4: 📊 СВОДКА ЗА МЕСЯЦ
A5: статья | B5: план | C5: факт | D5: разница
A6: 💰 Доходы | B6: =B22 -> 0 | C6: =C22 -> 0 | D6: =C6-B6 -> 0
A7: 🐷 Сбережения | B7: =B31 -> 0 | C7: =C31 -> 0 | D7: =C7-B7 -> 0
A8: 🏠 Постоянные расходы | B8: =B43 -> 0 | C8: =C43 -> 0 | D8: =B8-C8 -> 0
A9: 🛒 Переменные расходы | B9: =B63 -> 0 | C9: =C63 -> 0 | D9: =B9-C9 -> 0
A10: 🟢 Свободный остаток | B10: =B6-B7-B8-B9 -> 0 | C10: =C6-C7-C8-C9 -> 0 | D10: =C10-B10 -> 0
A13: 💰 ДОХОДЫ
A14: статья | B14: план | C14: факт | D14: разница
A15: Зарплата | D15: =C15-B15 -> 0
A16: Бонус/премия | D16: =C16-B16 -> 0
A17: Фриланс/подработка | D17: =C17-B17 -> 0
A18: Блог | D18: =C18-B18 -> 0
A19: Кэшбэк/проценты | D19: =C19-B19 -> 0
A20: Прочее | D20: =C20-B20 -> 0
A22: ВСЕГО | B22: =SUM(B15:B21) -> 0 | C22: =SUM(C15:C21) -> 0 | D22: =C22-B22 -> 0
A24: 🐷 СБЕРЕЖЕНИЯ
A25: статья | B25: план | C25: факт | D25: разница
A26: Финансовая подушка | D26: =C26-B26 -> 0
A27: Отпуск | D27: =C27-B27 -> 0
A28: Крупная цель | D28: =C28-B28 -> 0
A29: Налоги/запас | D29: =C29-B29 -> 0
A30: Прочее | D30: =C30-B30 -> 0
A31: ВСЕГО | B31: =SUM(B26:B30) -> 0 | C31: =SUM(C26:C30) -> 0 | D31: =C31-B31 -> 0
A33: 🏠 ПОСТОЯННЫЕ РАСХОДЫ
A34: статья | B34: план | C34: факт | D34: экономия
A35: Аренда/ипотека | D35: =B35-C35 -> 0
A36: Коммуналка | D36: =B36-C36 -> 0
A37: Связь/интернет | D37: =B37-C37 -> 0
A38: Кредиты | D38: =B38-C38 -> 0
A39: Страховка | D39: =B39-C39 -> 0
A40: Детсад/школа | D40: =B40-C40 -> 0
A41: Абонементы | D41: =B41-C41 -> 0
A42: Прочее | D42: =B42-C42 -> 0
A43: ВСЕГО | B43: =SUM(B35:B42) -> 0 | C43: =SUM(C35:C42) -> 0 | D43: =B43-C43 -> 0
A45: 🛒 ПЕРЕМЕННЫЕ РАСХОДЫ
A46: статья | B46: план | C46: факт | D46: экономия
A47: Продукты | D47: =B47-C47 -> 0
...

Sheet Август
A1: МОЙ БЮДЖЕТ 🩷 Август 2026
A2: не по сценарию · веду деньги без занудства
A4: 📊 СВОДКА ЗА МЕСЯЦ
A5: статья | B5: план | C5: факт | D5: разница
A6: 💰 Доходы | B6: =B22 -> 0 | C6: =C22 -> 0 | D6: =C6-B6 -> 0
A7: 🐷 Сбережения | B7: =B31 -> 0 | C7: =C31 -> 0 | D7: =C7-B7 -> 0
A8: 🏠 Постоянные расходы | B8: =B43 -> 0 | C8: =C43 -> 0 | D8: =B8-C8 -> 0
A9: 🛒 Переменные расходы | B9: =B63 -> 0 | C9: =C63 -> 0 | D9: =B9-C9 -> 0
A10: 🟢 Свободный остаток | B10: =B6-B7-B8-B9 -> 0 | C10: =C6-C7-C8-C9 -> 0 | D10: =C10-B10 -> 0
A13: 💰 ДОХОДЫ
A14: статья | B14: план | C14: факт | D14: разница
A15: Зарплата | D15: =C15-B15 -> 0
A16: Бонус/премия | D16: =C16-B16 -> 0
A17: Фриланс/подработка | D17: =C17-B17 -> 0
A18: Блог | D18: =C18-B18 -> 0
A19: Кэшбэк/проценты | D19: =C19-B19 -> 0
A20: Прочее | D20: =C20-B20 -> 0
A22: ВСЕГО | B22: =SUM(B15:B21) -> 0 | C22: =SUM(C15:C21) -> 0 | D22: =C22-B22 -> 0
A24: 🐷 СБЕРЕЖЕНИЯ
A25: статья | B25: план | C25: факт | D25: разница
A26: Финансовая подушка | D26: =C26-B26 -> 0
A27: Отпуск | D27: =C27-B27 -> 0
A28: Крупная цель | D28: =C28-B28 -> 0
A29: Налоги/запас | D29: =C29-B29 -> 0
A30: Прочее | D30: =C30-B30 -> 0
A31: ВСЕГО | B31: =SUM(B26:B30) -> 0 | C31: =SUM(C26:C30) -> 0 | D31: =C31-B31 -> 0
A33: 🏠 ПОСТОЯННЫЕ РАСХОДЫ
A34: статья | B34: план | C34: факт | D34: экономия
A35: Аренда/ипотека | D35: =B35-C35 -> 0
A36: Коммуналка | D36: =B36-C36 -> 0
A37: Связь/интернет | D37: =B37-C37 -> 0
A38: Кредиты | D38: =B38-C38 -> 0
A39: Страховка | D39: =B39-C39 -> 0
A40: Детсад/школа | D40: =B40-C40 -> 0
A41: Абонементы | D41: =B41-C41 -> 0
A42: Прочее | D42: =B42-C42 -> 0
A43: ВСЕГО | B43: =SUM(B35:B42) -> 0 | C43: =SUM(C35:C42) -> 0 | D43: =B43-C43 -> 0
A45: 🛒 ПЕРЕМЕННЫЕ РАСХОДЫ
A46: статья | B46: план | C46: факт | D46: экономия
A47: Продукты | D47: =B47-C47 -> 0
...

Sheet Сентябрь
A1: МОЙ БЮДЖЕТ 🩷 Сентябрь 2026
A2: не по сценарию · веду деньги без занудства
A4: 📊 СВОДКА ЗА МЕСЯЦ
A5: статья | B5: план | C5: факт | D5: разница
A6: 💰 Доходы | B6: =B22 -> 0 | C6: =C22 -> 0 | D6: =C6-B6 -> 0
A7: 🐷 Сбережения | B7: =B31 -> 0 | C7: =C31 -> 0 | D7: =C7-B7 -> 0
A8: 🏠 Постоянные расходы | B8: =B43 -> 0 | C8: =C43 -> 0 | D8: =B8-C8 -> 0
A9: 🛒 Переменные расходы | B9: =B63 -> 0 | C9: =C63 -> 0 | D9: =B9-C9 -> 0
A10: 🟢 Свободный остаток | B10: =B6-B7-B8-B9 -> 0 | C10: =C6-C7-C8-C9 -> 0 | D10: =C10-B10 -> 0
A13: 💰 ДОХОДЫ
A14: статья | B14: план | C14: факт | D14: разница
A15: Зарплата | D15: =C15-B15 -> 0
A16: Бонус/премия | D16: =C16-B16 -> 0
A17: Фриланс/подработка | D17: =C17-B17 -> 0
A18: Блог | D18: =C18-B18 -> 0
A19: Кэшбэк/проценты | D19: =C19-B19 -> 0
A20: Прочее | D20: =C20-B20 -> 0
A22: ВСЕГО | B22: =SUM(B15:B21) -> 0 | C22: =SUM(C15:C21) -> 0 | D22: =C22-B22 -> 0
A24: 🐷 СБЕРЕЖЕНИЯ
A25: статья | B25: план | C25: факт | D25: разница
A26: Финансовая подушка | D26: =C26-B26 -> 0
A27: Отпуск | D27: =C27-B27 -> 0
A28: Крупная цель | D28: =C28-B28 -> 0
A29: Налоги/запас | D29: =C29-B29 -> 0
A30: Прочее | D30: =C30-B30 -> 0
A31: ВСЕГО | B31: =SUM(B26:B30) -> 0 | C31: =SUM(C26:C30) -> 0 | D31: =C31-B31 -> 0
A33: 🏠 ПОСТОЯННЫЕ РАСХОДЫ
A34: статья | B34: план | C34: факт | D34: экономия
A35: Аренда/ипотека | D35: =B35-C35 -> 0
A36: Коммуналка | D36: =B36-C36 -> 0
A37: Связь/интернет | D37: =B37-C37 -> 0
A38: Кредиты | D38: =B38-C38 -> 0
A39: Страховка | D39: =B39-C39 -> 0
A40: Детсад/школа | D40: =B40-C40 -> 0
A41: Абонементы | D41: =B41-C41 -> 0
A42: Прочее | D42: =B42-C42 -> 0
A43: ВСЕГО | B43: =SUM(B35:B42) -> 0 | C43: =SUM(C35:C42) -> 0 | D43: =B43-C43 -> 0
A45: 🛒 ПЕРЕМЕННЫЕ РАСХОДЫ
A46: статья | B46: план | C46: факт | D46: экономия
A47: Продукты | D47: =B47-C47 -> 0
...

Sheet Октябрь
A1: МОЙ БЮДЖЕТ 🩷 Октябрь 2026
A2: не по сценарию · веду деньги без занудства
A4: 📊 СВОДКА ЗА МЕСЯЦ
A5: статья | B5: план | C5: факт | D5: разница
A6: 💰 Доходы | B6: =B22 -> 0 | C6: =C22 -> 0 | D6: =C6-B6 -> 0
A7: 🐷 Сбережения | B7: =B31 -> 0 | C7: =C31 -> 0 | D7: =C7-B7 -> 0
A8: 🏠 Постоянные расходы | B8: =B43 -> 0 | C8: =C43 -> 0 | D8: =B8-C8 -> 0
A9: 🛒 Переменные расходы | B9: =B63 -> 0 | C9: =C63 -> 0 | D9: =B9-C9 -> 0
A10: 🟢 Свободный остаток | B10: =B6-B7-B8-B9 -> 0 | C10: =C6-C7-C8-C9 -> 0 | D10: =C10-B10 -> 0
A13: 💰 ДОХОДЫ
A14: статья | B14: план | C14: факт | D14: разница
A15: Зарплата | D15: =C15-B15 -> 0
A16: Бонус/премия | D16: =C16-B16 -> 0
A17: Фриланс/подработка | D17: =C17-B17 -> 0
A18: Блог | D18: =C18-B18 -> 0
A19: Кэшбэк/проценты | D19: =C19-B19 -> 0
A20: Прочее | D20: =C20-B20 -> 0
A22: ВСЕГО | B22: =SUM(B15:B21) -> 0 | C22: =SUM(C15:C21) -> 0 | D22: =C22-B22 -> 0
A24: 🐷 СБЕРЕЖЕНИЯ
A25: статья | B25: план | C25: факт | D25: разница
A26: Финансовая подушка | D26: =C26-B26 -> 0
A27: Отпуск | D27: =C27-B27 -> 0
A28: Крупная цель | D28: =C28-B28 -> 0
A29: Налоги/запас | D29: =C29-B29 -> 0
A30: Прочее | D30: =C30-B30 -> 0
A31: ВСЕГО | B31: =SUM(B26:B30) -> 0 | C31: =SUM(C26:C30) -> 0 | D31: =C31-B31 -> 0
A33: 🏠 ПОСТОЯННЫЕ РАСХОДЫ
A34: статья | B34: план | C34: факт | D34: экономия
A35: Аренда/ипотека | D35: =B35-C35 -> 0
A36: Коммуналка | D36: =B36-C36 -> 0
A37: Связь/интернет | D37: =B37-C37 -> 0
A38: Кредиты | D38: =B38-C38 -> 0
A39: Страховка | D39: =B39-C39 -> 0
A40: Детсад/школа | D40: =B40-C40 -> 0
A41: Абонементы | D41: =B41-C41 -> 0
A42: Прочее | D42: =B42-C42 -> 0
A43: ВСЕГО | B43: =SUM(B35:B42) -> 0 | C43: =SUM(C35:C42) -> 0 | D43: =B43-C43 -> 0
A45: 🛒 ПЕРЕМЕННЫЕ РАСХОДЫ
A46: статья | B46: план | C46: факт | D46: экономия
A47: Продукты | D47: =B47-C47 -> 0
...

Sheet Ноябрь
A1: МОЙ БЮДЖЕТ 🩷 Ноябрь 2026
A2: не по сценарию · веду деньги без занудства
A4: 📊 СВОДКА ЗА МЕСЯЦ
A5: статья | B5: план | C5: факт | D5: разница
A6: 💰 Доходы | B6: =B22 -> 0 | C6: =C22 -> 0 | D6: =C6-B6 -> 0
A7: 🐷 Сбережения | B7: =B31 -> 0 | C7: =C31 -> 0 | D7: =C7-B7 -> 0
A8: 🏠 Постоянные расходы | B8: =B43 -> 0 | C8: =C43 -> 0 | D8: =B8-C8 -> 0
A9: 🛒 Переменные расходы | B9: =B63 -> 0 | C9: =C63 -> 0 | D9: =B9-C9 -> 0
A10: 🟢 Свободный остаток | B10: =B6-B7-B8-B9 -> 0 | C10: =C6-C7-C8-C9 -> 0 | D10: =C10-B10 -> 0
A13: 💰 ДОХОДЫ
A14: статья | B14: план | C14: факт | D14: разница
A15: Зарплата | D15: =C15-B15 -> 0
A16: Бонус/премия | D16: =C16-B16 -> 0
A17: Фриланс/подработка | D17: =C17-B17 -> 0
A18: Блог | D18: =C18-B18 -> 0
A19: Кэшбэк/проценты | D19: =C19-B19 -> 0
A20: Прочее | D20: =C20-B20 -> 0
A22: ВСЕГО | B22: =SUM(B15:B21) -> 0 | C22: =SUM(C15:C21) -> 0 | D22: =C22-B22 -> 0
A24: 🐷 СБЕРЕЖЕНИЯ
A25: статья | B25: план | C25: факт | D25: разница
A26: Финансовая подушка | D26: =C26-B26 -> 0
A27: Отпуск | D27: =C27-B27 -> 0
A28: Крупная цель | D28: =C28-B28 -> 0
A29: Налоги/запас | D29: =C29-B29 -> 0
A30: Прочее | D30: =C30-B30 -> 0
A31: ВСЕГО | B31: =SUM(B26:B30) -> 0 | C31: =SUM(C26:C30) -> 0 | D31: =C31-B31 -> 0
A33: 🏠 ПОСТОЯННЫЕ РАСХОДЫ
A34: статья | B34: план | C34: факт | D34: экономия
A35: Аренда/ипотека | D35: =B35-C35 -> 0
A36: Коммуналка | D36: =B36-C36 -> 0
A37: Связь/интернет | D37: =B37-C37 -> 0
A38: Кредиты | D38: =B38-C38 -> 0
A39: Страховка | D39: =B39-C39 -> 0
A40: Детсад/школа | D40: =B40-C40 -> 0
A41: Абонементы | D41: =B41-C41 -> 0
A42: Прочее | D42: =B42-C42 -> 0
A43: ВСЕГО | B43: =SUM(B35:B42) -> 0 | C43: =SUM(C35:C42) -> 0 | D43: =B43-C43 -> 0
A45: 🛒 ПЕРЕМЕННЫЕ РАСХОДЫ
A46: статья | B46: план | C46: факт | D46: экономия
A47: Продукты | D47: =B47-C47 -> 0
...

Sheet Декабрь
A1: МОЙ БЮДЖЕТ 🩷 Декабрь 2026
A2: не по сценарию · веду деньги без занудства
A4: 📊 СВОДКА ЗА МЕСЯЦ
A5: статья | B5: план | C5: факт | D5: разница
A6: 💰 Доходы | B6: =B22 -> 0 | C6: =C22 -> 0 | D6: =C6-B6 -> 0
A7: 🐷 Сбережения | B7: =B31 -> 0 | C7: =C31 -> 0 | D7: =C7-B7 -> 0
A8: 🏠 Постоянные расходы | B8: =B43 -> 0 | C8: =C43 -> 0 | D8: =B8-C8 -> 0
A9: 🛒 Переменные расходы | B9: =B63 -> 0 | C9: =C63 -> 0 | D9: =B9-C9 -> 0
A10: 🟢 Свободный остаток | B10: =B6-B7-B8-B9 -> 0 | C10: =C6-C7-C8-C9 -> 0 | D10: =C10-B10 -> 0
A13: 💰 ДОХОДЫ
A14: статья | B14: план | C14: факт | D14: разница
A15: Зарплата | D15: =C15-B15 -> 0
A16: Бонус/премия | D16: =C16-B16 -> 0
A17: Фриланс/подработка | D17: =C17-B17 -> 0
A18: Блог | D18: =C18-B18 -> 0
A19: Кэшбэк/проценты | D19: =C19-B19 -> 0
A20: Прочее | D20: =C20-B20 -> 0
A22: ВСЕГО | B22: =SUM(B15:B21) -> 0 | C22: =SUM(C15:C21) -> 0 | D22: =C22-B22 -> 0
A24: 🐷 СБЕРЕЖЕНИЯ
A25: статья | B25: план | C25: факт | D25: разница
A26: Финансовая подушка | D26: =C26-B26 -> 0
A27: Отпуск | D27: =C27-B27 -> 0
A28: Крупная цель | D28: =C28-B28 -> 0
A29: Налоги/запас | D29: =C29-B29 -> 0
A30: Прочее | D30: =C30-B30 -> 0
A31: ВСЕГО | B31: =SUM(B26:B30) -> 0 | C31: =SUM(C26:C30) -> 0 | D31: =C31-B31 -> 0
A33: 🏠 ПОСТОЯННЫЕ РАСХОДЫ
A34: статья | B34: план | C34: факт | D34: экономия
A35: Аренда/ипотека | D35: =B35-C35 -> 0
A36: Коммуналка | D36: =B36-C36 -> 0
A37: Связь/интернет | D37: =B37-C37 -> 0
A38: Кредиты | D38: =B38-C38 -> 0
A39: Страховка | D39: =B39-C39 -> 0
A40: Детсад/школа | D40: =B40-C40 -> 0
A41: Абонементы | D41: =B41-C41 -> 0
A42: Прочее | D42: =B42-C42 -> 0
A43: ВСЕГО | B43: =SUM(B35:B42) -> 0 | C43: =SUM(C35:C42) -> 0 | D43: =B43-C43 -> 0
A45: 🛒 ПЕРЕМЕННЫЕ РАСХОДЫ
A46: статья | B46: план | C46: факт | D46: экономия
A47: Продукты | D47: =B47-C47 -> 0
...
